2024-03-27 09:46:09,295 DEBUG    root            Loaded Command Group: ['gcloud', 'auth']
2024-03-27 09:46:09,305 DEBUG    root            Loaded Command Group: ['gcloud', 'auth', 'login']
2024-03-27 09:46:09,307 DEBUG    root            Running [gcloud.auth.login] with arguments: []
2024-03-27 09:46:09,350 DEBUG    requests_oauthlib.oauth2_session Generated new state DySDKgct0Dz2EvJA0SP1JQnE5o08OV.
2024-03-27 09:46:09,350 INFO     ___FILE_ONLY___ Go to the following link in your browser:

    https://accounts.google.com/o/oauth2/auth?response_type=code&client_id=32555940559.apps.googleusercontent.com&redirect_uri=https%3A%2F%2Fsdk.cloud.google.com%2Fauthcode.html&scope=openid+https%3A%2F%2Fwww.googleapis.com%2Fauth%2Fuserinfo.email+https%3A%2F%2Fwww.googleapis.com%2Fauth%2Fcloud-platform+https%3A%2F%2Fwww.googleapis.com%2Fauth%2Fappengine.admin+https%3A%2F%2Fwww.googleapis.com%2Fauth%2Fsqlservice.login+https%3A%2F%2Fwww.googleapis.com%2Fauth%2Fcompute+https%3A%2F%2Fwww.googleapis.com%2Fauth%2Faccounts.reauth&state=DySDKgct0Dz2EvJA0SP1JQnE5o08OV&prompt=consent&token_usage=remote&access_type=offline&code_challenge=BxjVmvdRzWIsKTwtXRi1-pUL11IJ1NllyIkEda6pxPk&code_challenge_method=S256


2024-03-27 09:58:10,979 DEBUG    requests_oauthlib.oauth2_session Requesting url https://oauth2.googleapis.com/token using method POST.
2024-03-27 09:58:10,979 DEBUG    requests_oauthlib.oauth2_session Supplying headers {b'Accept': b'application/json', b'Content-Type': b'application/x-www-form-urlencoded;charset=UTF-8', b'user-agent': b'google-cloud-sdk gcloud/470.0.0 command/gcloud.auth.login invocation-id/102f22c71ba14642839bf628e23b0034 environment/None environment-version/None client-os/LINUX client-os-ver/6.5.0 client-pltf-arch/x86_64 interactive/True from-script/False python/3.11.8 term/xterm-256color (Linux 6.5.0-1014-aws)'} and data {'grant_type': 'authorization_code', 'client_id': '32555940559.apps.googleusercontent.com', 'client_secret': 'ZmssLNjJy2998hD4CTg2ejr2', 'code': 'clear', 'redirect_uri': 'https://sdk.cloud.google.com/authcode.html', 'code_verifier': 'Ic17IDN.qQ2ywwhOwtfMDUoh0o8GHgw~9W4rWcO4iTFEhsle_lnipwuh~ErItTB82wwcAm.sPEpgOoRqPfvQaGaVF1Is-XFDaZcAu_hRhcyRtQBtBXqyuh~GjUKKe2_N'}
2024-03-27 09:58:10,979 DEBUG    requests_oauthlib.oauth2_session Passing through key word arguments {'json': None, 'timeout': None, 'auth': None, 'verify': None, 'proxies': None}.
2024-03-27 09:58:10,981 DEBUG    urllib3.connectionpool Starting new HTTPS connection (1): oauth2.googleapis.com:443
2024-03-27 09:58:11,165 DEBUG    urllib3.connectionpool https://oauth2.googleapis.com:443 "POST /token HTTP/1.1" 400 None
2024-03-27 09:58:11,167 DEBUG    requests_oauthlib.oauth2_session Prepared fetch token request body grant_type=authorization_code&client_id=32555940559.apps.googleusercontent.com&client_secret=ZmssLNjJy2998hD4CTg2ejr2&code=clear&redirect_uri=https%3A%2F%2Fsdk.cloud.google.com%2Fauthcode.html&code_verifier=Ic17IDN.qQ2ywwhOwtfMDUoh0o8GHgw~9W4rWcO4iTFEhsle_lnipwuh~ErItTB82wwcAm.sPEpgOoRqPfvQaGaVF1Is-XFDaZcAu_hRhcyRtQBtBXqyuh~GjUKKe2_N
2024-03-27 09:58:11,167 DEBUG    requests_oauthlib.oauth2_session Request to fetch token completed with status 400.
2024-03-27 09:58:11,167 DEBUG    requests_oauthlib.oauth2_session Request headers were {'user-agent': b'google-cloud-sdk gcloud/470.0.0 command/gcloud.auth.login invocation-id/102f22c71ba14642839bf628e23b0034 environment/None environment-version/None client-os/LINUX client-os-ver/6.5.0 client-pltf-arch/x86_64 interactive/True from-script/False python/3.11.8 term/xterm-256color (Linux 6.5.0-1014-aws)', 'Accept-Encoding': 'gzip, deflate', 'Accept': b'application/json', 'Connection': 'keep-alive', 'Content-Type': b'application/x-www-form-urlencoded;charset=UTF-8', 'Content-Length': '335'}
2024-03-27 09:58:11,167 DEBUG    requests_oauthlib.oauth2_session Request body was grant_type=authorization_code&client_id=32555940559.apps.googleusercontent.com&client_secret=ZmssLNjJy2998hD4CTg2ejr2&code=clear&redirect_uri=https%3A%2F%2Fsdk.cloud.google.com%2Fauthcode.html&code_verifier=Ic17IDN.qQ2ywwhOwtfMDUoh0o8GHgw~9W4rWcO4iTFEhsle_lnipwuh~ErItTB82wwcAm.sPEpgOoRqPfvQaGaVF1Is-XFDaZcAu_hRhcyRtQBtBXqyuh~GjUKKe2_N
2024-03-27 09:58:11,167 DEBUG    requests_oauthlib.oauth2_session Response headers were {'Cache-Control': 'no-cache, no-store, max-age=0, must-revalidate', 'Expires': 'Mon, 01 Jan 1990 00:00:00 GMT', 'Pragma': 'no-cache', 'Date': 'Wed, 27 Mar 2024 09:58:11 GMT', 'Content-Type': 'application/json; charset=utf-8', 'Vary': 'Origin, X-Origin, Referer', 'Content-Encoding': 'gzip', 'Server': 'scaffolding on HTTPServer2', 'X-XSS-Protection': '0', 'X-Frame-Options': 'SAMEORIGIN', 'X-Content-Type-Options': 'nosniff', 'Alt-Svc': 'h3=":443"; ma=2592000,h3-29=":443"; ma=2592000', 'Transfer-Encoding': 'chunked'} and content {
  "error": "invalid_grant",
  "error_description": "Malformed auth code."
}.
2024-03-27 09:58:11,167 DEBUG    requests_oauthlib.oauth2_session Invoking 0 token response hooks.
2024-03-27 09:58:11,168 DEBUG    root            (invalid_grant) Malformed auth code.
Traceback (most recent call last):
  File "/usr/bin/../lib/google-cloud-sdk/lib/googlecloudsdk/calliope/cli.py", line 998, in Execute
    resources = calliope_command.Run(cli=self, args=args)
                ^^^^^^^^^^^^^^^^^^^^^^^^^^^^^^^^^^^^^^^^^
  File "/usr/bin/../lib/google-cloud-sdk/lib/googlecloudsdk/calliope/backend.py", line 815, in Run
    resources = command_instance.Run(args)
                ^^^^^^^^^^^^^^^^^^^^^^^^^^
  File "/usr/bin/../lib/google-cloud-sdk/lib/surface/auth/login.py", line 334, in Run
    creds = auth_util.DoInstalledAppBrowserFlowGoogleAuth(
            ^^^^^^^^^^^^^^^^^^^^^^^^^^^^^^^^^^^^^^^^^^^^^^
  File "/usr/bin/../lib/google-cloud-sdk/lib/googlecloudsdk/api_lib/auth/util.py", line 329, in DoInstalledAppBrowserFlowGoogleAuth
    user_creds = RemoteLoginWithAuthProxyFlowRunner(
                 ^^^^^^^^^^^^^^^^^^^^^^^^^^^^^^^^^^^
  File "/usr/bin/../lib/google-cloud-sdk/lib/googlecloudsdk/api_lib/auth/util.py", line 144, in Run
    return self._flow.Run(**kwargs)
           ^^^^^^^^^^^^^^^^^^^^^^^^
  File "/usr/bin/../lib/google-cloud-sdk/lib/googlecloudsdk/core/credentials/flow.py", line 237, in Run
    return self._Run(**kwargs)
           ^^^^^^^^^^^^^^^^^^^
  File "/usr/bin/../lib/google-cloud-sdk/lib/googlecloudsdk/core/credentials/flow.py", line 743, in _Run
    self.fetch_token(
  File "/usr/bin/../lib/google-cloud-sdk/lib/third_party/google_auth_oauthlib/flow.py", line 300, in fetch_token
    return self.oauth2session.fetch_token(self.client_config["token_uri"], **kwargs)
           ^^^^^^^^^^^^^^^^^^^^^^^^^^^^^^^^^^^^^^^^^^^^^^^^^^^^^^^^^^^^^^^^^^^^^^^^^
  File "/usr/bin/../lib/google-cloud-sdk/lib/third_party/requests_oauthlib/oauth2_session.py", line 345, in fetch_token
    self._client.parse_request_body_response(r.text, scope=self.scope)
  File "/usr/bin/../lib/google-cloud-sdk/lib/third_party/oauthlib/oauth2/rfc6749/clients/base.py", line 451, in parse_request_body_response
    self.token = parse_token_response(body, scope=scope)
                 ^^^^^^^^^^^^^^^^^^^^^^^^^^^^^^^^^^^^^^^
  File "/usr/bin/../lib/google-cloud-sdk/lib/third_party/oauthlib/oauth2/rfc6749/parameters.py", line 435, in parse_token_response
    validate_token_parameters(params)
  File "/usr/bin/../lib/google-cloud-sdk/lib/third_party/oauthlib/oauth2/rfc6749/parameters.py", line 442, in validate_token_parameters
    raise_from_error(params.get('error'), params)
  File "/usr/bin/../lib/google-cloud-sdk/lib/third_party/oauthlib/oauth2/rfc6749/errors.py", line 406, in raise_from_error
    raise cls(**kwargs)
oauthlib.oauth2.rfc6749.errors.InvalidGrantError: (invalid_grant) Malformed auth code.
2024-03-27 09:58:11,180 ERROR    ___FILE_ONLY___ BEGIN CRASH STACKTRACE
Traceback (most recent call last):
  File "/usr/bin/../lib/google-cloud-sdk/lib/googlecloudsdk/command_lib/crash_handling.py", line 199, in Wrapper
    target_function(*args, **kwargs)
  File "/usr/bin/../lib/google-cloud-sdk/lib/googlecloudsdk/gcloud_main.py", line 193, in main
    gcloud_cli.Execute()
  File "/usr/bin/../lib/google-cloud-sdk/lib/googlecloudsdk/calliope/cli.py", line 1024, in Execute
    self._HandleAllErrors(exc, command_path_string, specified_arg_names)
  File "/usr/bin/../lib/google-cloud-sdk/lib/googlecloudsdk/calliope/cli.py", line 1061, in _HandleAllErrors
    exceptions.HandleError(exc, command_path_string, self.__known_error_handler)
  File "/usr/bin/../lib/google-cloud-sdk/lib/googlecloudsdk/calliope/exceptions.py", line 557, in HandleError
    core_exceptions.reraise(exc)
  File "/usr/bin/../lib/google-cloud-sdk/lib/googlecloudsdk/core/exceptions.py", line 146, in reraise
    six.reraise(type(exc_value), exc_value, tb)
  File "/usr/bin/../lib/google-cloud-sdk/lib/third_party/six/__init__.py", line 719, in reraise
    raise value
  File "/usr/bin/../lib/google-cloud-sdk/lib/googlecloudsdk/calliope/cli.py", line 998, in Execute
    resources = calliope_command.Run(cli=self, args=args)
                ^^^^^^^^^^^^^^^^^^^^^^^^^^^^^^^^^^^^^^^^^
  File "/usr/bin/../lib/google-cloud-sdk/lib/googlecloudsdk/calliope/backend.py", line 815, in Run
    resources = command_instance.Run(args)
                ^^^^^^^^^^^^^^^^^^^^^^^^^^
  File "/usr/bin/../lib/google-cloud-sdk/lib/surface/auth/login.py", line 334, in Run
    creds = auth_util.DoInstalledAppBrowserFlowGoogleAuth(
            ^^^^^^^^^^^^^^^^^^^^^^^^^^^^^^^^^^^^^^^^^^^^^^
  File "/usr/bin/../lib/google-cloud-sdk/lib/googlecloudsdk/api_lib/auth/util.py", line 329, in DoInstalledAppBrowserFlowGoogleAuth
    user_creds = RemoteLoginWithAuthProxyFlowRunner(
                 ^^^^^^^^^^^^^^^^^^^^^^^^^^^^^^^^^^^
  File "/usr/bin/../lib/google-cloud-sdk/lib/googlecloudsdk/api_lib/auth/util.py", line 144, in Run
    return self._flow.Run(**kwargs)
           ^^^^^^^^^^^^^^^^^^^^^^^^
  File "/usr/bin/../lib/google-cloud-sdk/lib/googlecloudsdk/core/credentials/flow.py", line 237, in Run
    return self._Run(**kwargs)
           ^^^^^^^^^^^^^^^^^^^
  File "/usr/bin/../lib/google-cloud-sdk/lib/googlecloudsdk/core/credentials/flow.py", line 743, in _Run
    self.fetch_token(
  File "/usr/bin/../lib/google-cloud-sdk/lib/third_party/google_auth_oauthlib/flow.py", line 300, in fetch_token
    return self.oauth2session.fetch_token(self.client_config["token_uri"], **kwargs)
           ^^^^^^^^^^^^^^^^^^^^^^^^^^^^^^^^^^^^^^^^^^^^^^^^^^^^^^^^^^^^^^^^^^^^^^^^^
  File "/usr/bin/../lib/google-cloud-sdk/lib/third_party/requests_oauthlib/oauth2_session.py", line 345, in fetch_token
    self._client.parse_request_body_response(r.text, scope=self.scope)
  File "/usr/bin/../lib/google-cloud-sdk/lib/third_party/oauthlib/oauth2/rfc6749/clients/base.py", line 451, in parse_request_body_response
    self.token = parse_token_response(body, scope=scope)
                 ^^^^^^^^^^^^^^^^^^^^^^^^^^^^^^^^^^^^^^^
  File "/usr/bin/../lib/google-cloud-sdk/lib/third_party/oauthlib/oauth2/rfc6749/parameters.py", line 435, in parse_token_response
    validate_token_parameters(params)
  File "/usr/bin/../lib/google-cloud-sdk/lib/third_party/oauthlib/oauth2/rfc6749/parameters.py", line 442, in validate_token_parameters
    raise_from_error(params.get('error'), params)
  File "/usr/bin/../lib/google-cloud-sdk/lib/third_party/oauthlib/oauth2/rfc6749/errors.py", line 406, in raise_from_error
    raise cls(**kwargs)
oauthlib.oauth2.rfc6749.errors.InvalidGrantError: (invalid_grant) Malformed auth code.
2024-03-27 09:58:11,186 ERROR    root            gcloud crashed (InvalidGrantError): (invalid_grant) Malformed auth code.
2024-03-27 09:58:11,186 INFO     ___FILE_ONLY___ 
If you would like to report this issue, please run the following command:

2024-03-27 09:58:11,187 INFO     ___FILE_ONLY___   gcloud feedback

2024-03-27 09:58:11,187 INFO     ___FILE_ONLY___ 
To check gcloud for common problems, please run the following command:

2024-03-27 09:58:11,187 INFO     ___FILE_ONLY___   gcloud info --run-diagnostics

